ERROR 2018-11-16 09:53:08,411 exception 135 Internal Server Error: /sms_code/13711111111/
Traceback (most recent call last):
  File "/home/python/.virtualenvs/django_env/lib/python3.5/site-packages/django/core/handlers/exception.py", line 41, in inner
    response = get_response(request)
  File "/home/python/.virtualenvs/django_env/lib/python3.5/site-packages/django/core/handlers/base.py", line 187, in _get_response
    response = self.process_exception_by_middleware(e, request)
  File "/home/python/.virtualenvs/django_env/lib/python3.5/site-packages/django/core/handlers/base.py", line 185, in _get_response
    response = wrapped_callback(request, *callback_args, **callback_kwargs)
  File "/home/python/.virtualenvs/django_env/lib/python3.5/site-packages/django/views/decorators/csrf.py", line 58, in wrapped_view
    return view_func(*args, **kwargs)
  File "/home/python/.virtualenvs/django_env/lib/python3.5/site-packages/django/views/generic/base.py", line 68, in view
    return self.dispatch(request, *args, **kwargs)
  File "/home/python/.virtualenvs/django_env/lib/python3.5/site-packages/rest_framework/views.py", line 495, in dispatch
    response = self.handle_exception(exc)
  File "/home/python/.virtualenvs/django_env/lib/python3.5/site-packages/rest_framework/views.py", line 455, in handle_exception
    self.raise_uncaught_exception(exc)
  File "/home/python/.virtualenvs/django_env/lib/python3.5/site-packages/rest_framework/views.py", line 492, in dispatch
    response = handler(request, *args, **kwargs)
  File "/home/python/Desktop/django_meiduo/meiduo/meiduo_mall/meiduo_mall/apps/users/views.py", line 15, in get
    sms_code='06d'%randint(0,999999)
TypeError: not all arguments converted during string formatting
ERROR 2018-11-16 09:53:08,635 basehttp 124 "GET /sms_code/13711111111/ HTTP/1.1" 500 17448
ERROR 2018-11-16 09:56:25,702 exception 135 Internal Server Error: /sms_code/13711111111/
Traceback (most recent call last):
  File "/home/python/.virtualenvs/django_env/lib/python3.5/site-packages/django/core/handlers/exception.py", line 41, in inner
    response = get_response(request)
  File "/home/python/.virtualenvs/django_env/lib/python3.5/site-packages/django/core/handlers/base.py", line 187, in _get_response
    response = self.process_exception_by_middleware(e, request)
  File "/home/python/.virtualenvs/django_env/lib/python3.5/site-packages/django/core/handlers/base.py", line 185, in _get_response
    response = wrapped_callback(request, *callback_args, **callback_kwargs)
  File "/home/python/.virtualenvs/django_env/lib/python3.5/site-packages/django/views/decorators/csrf.py", line 58, in wrapped_view
    return view_func(*args, **kwargs)
  File "/home/python/.virtualenvs/django_env/lib/python3.5/site-packages/django/views/generic/base.py", line 68, in view
    return self.dispatch(request, *args, **kwargs)
  File "/home/python/.virtualenvs/django_env/lib/python3.5/site-packages/rest_framework/views.py", line 495, in dispatch
    response = self.handle_exception(exc)
  File "/home/python/.virtualenvs/django_env/lib/python3.5/site-packages/rest_framework/views.py", line 455, in handle_exception
    self.raise_uncaught_exception(exc)
  File "/home/python/.virtualenvs/django_env/lib/python3.5/site-packages/rest_framework/views.py", line 492, in dispatch
    response = handler(request, *args, **kwargs)
  File "/home/python/Desktop/django_meiduo/meiduo/meiduo_mall/meiduo_mall/apps/users/views.py", line 15, in get
    sms_code='06d'%randint(0,999999)
TypeError: not all arguments converted during string formatting
ERROR 2018-11-16 09:56:25,818 basehttp 124 "GET /sms_code/13711111111/ HTTP/1.1" 500 18116
ERROR 2018-11-16 09:58:12,938 exception 135 Internal Server Error: /sms_code/13711111111/
Traceback (most recent call last):
  File "/home/python/.virtualenvs/django_env/lib/python3.5/site-packages/django/core/handlers/exception.py", line 41, in inner
    response = get_response(request)
  File "/home/python/.virtualenvs/django_env/lib/python3.5/site-packages/django/core/handlers/base.py", line 187, in _get_response
    response = self.process_exception_by_middleware(e, request)
  File "/home/python/.virtualenvs/django_env/lib/python3.5/site-packages/django/core/handlers/base.py", line 185, in _get_response
    response = wrapped_callback(request, *callback_args, **callback_kwargs)
  File "/home/python/.virtualenvs/django_env/lib/python3.5/site-packages/django/views/decorators/csrf.py", line 58, in wrapped_view
    return view_func(*args, **kwargs)
  File "/home/python/.virtualenvs/django_env/lib/python3.5/site-packages/django/views/generic/base.py", line 68, in view
    return self.dispatch(request, *args, **kwargs)
  File "/home/python/.virtualenvs/django_env/lib/python3.5/site-packages/rest_framework/views.py", line 495, in dispatch
    response = self.handle_exception(exc)
  File "/home/python/.virtualenvs/django_env/lib/python3.5/site-packages/rest_framework/views.py", line 455, in handle_exception
    self.raise_uncaught_exception(exc)
  File "/home/python/.virtualenvs/django_env/lib/python3.5/site-packages/rest_framework/views.py", line 492, in dispatch
    response = handler(request, *args, **kwargs)
  File "/home/python/Desktop/django_meiduo/meiduo/meiduo_mall/meiduo_mall/apps/users/views.py", line 17, in get
    coon=get_redis_connection(sms_code)
  File "/home/python/.virtualenvs/django_env/lib/python3.5/site-packages/django_redis/__init__.py", line 14, in get_redis_connection
    cache = caches[alias]
  File "/home/python/.virtualenvs/django_env/lib/python3.5/site-packages/django/core/cache/__init__.py", line 77, in __getitem__
    "Could not find config for '%s' in settings.CACHES" % alias
django.core.cache.backends.base.InvalidCacheBackendError: Could not find config for '130253' in settings.CACHES
ERROR 2018-11-16 09:58:32,376 basehttp 124 "GET /sms_code/13711111111/ HTTP/1.1" 500 18505
